try{
     alert("Hi");
    alert(x);
     
}
catch(err)
{
    alert("Inside catch block");
    console.log(err);
}
finally{
    alert("Hello");
}